{"special":"The problem can be corrected by updating your system to the following package versions:\nIn general, a standard system update will make all the necessary changes.","threat":["A remote attacker could possibly use this issue to spoof headers in certain environments.","A remote attacker could possibly use this issue to perform a cross-site scripting attack.","A remote attacker could possibly use this issue to cause Django to consume resources, resulting in a denial of service.","A remote attacker could possibly use this issue to cause a large number of SQL queries, resulting in a database denial of service."],"update":{"14.04":[{"package":"python-django","version":"1.6.1-2ubuntu0.6"}],"10.04":[{"version":"1.1.1-2ubuntu1.14","package":"python-django"}],"14.10":[{"version":"1.6.6-1ubuntu2.1","package":"python-django"},{"version":"1.6.6-1ubuntu2.1","package":"python3-django"}],"12.04":[{"version":"1.3.1-4ubuntu1.13","package":"python-django"}]},"date":"January 13, 2015","usn":"USN-2469-1","info":"python-django vulnerabilities","CVEs":["CVE-2015-0219","CVE-2015-0220","CVE-2015-0221","CVE-2015-0222"]}