{"update":{"12.04":[{"version":"3.2.3-0ubuntu3.2","package":"python3.2"},{"package":"python3.2-minimal","version":"3.2.3-0ubuntu3.2"}],"11.04":[{"package":"python3.2","version":"3.2-1ubuntu1.2"},{"package":"python3.2-minimal","version":"3.2-1ubuntu1.2"}],"12.10":[{"version":"3.2.3-6ubuntu3.1","package":"python3.2"},{"version":"3.2.3-6ubuntu3.1","package":"python3.2-minimal"}],"11.10":[{"version":"3.2.2-0ubuntu1.1","package":"python3.2"},{"version":"3.2.2-0ubuntu1.1","package":"python3.2-minimal"}]},"special":"The problem can be corrected by updating your system to the following package versions:\nIn general, a standard system update will make all the necessary changes.","usn":"USN-1615-1","info":"python3.2 vulnerabilities","date":"October 23, 2012","threat":["A local attacker could exploit this to obtain sensitive information.","A remote attacker could exploit this to cause a denial of service via excessive CPU utilization.","An attacker could cause a denial of service under certian circumstances.","An attacker could exploit this to cause a denial of service via memory corruption."],"CVEs":["CVE-2011-4944","CVE-2012-0845","CVE-2012-1150","CVE-2012-2135"]}